<?xml version="1.0" ?>
<!-- =================================================================================== -->
<!-- |    This document was autogenerated by xacro from ur10_robot.urdf.xacro          | -->
<!-- |    EDITING THIS FILE BY HAND IS NOT RECOMMENDED                                 | -->
<!-- =================================================================================== -->
<robot name="ur10" xmlns:xacro="http://ros.org/wiki/xacro">
  <gazebo>
    <plugin filename="libgazebo_ros_control.so" name="ros_control">
      <!--robotNamespace>/</robotNamespace-->
      <!--robotSimType>gazebo_ros_control/DefaultRobotHWSim</robotSimType-->
    </plugin>
  </gazebo>
  <!--
  Author: Kelsey Hawkins
  Contributers: Jimmy Da Silva, Ajit Krisshna N L, Muhammad Asif Rana
-->
  <!-- measured from model -->

  <!-- nothing to do here at the moment -->
  <!-- ROS base_link to UR 'Base' Coordinates transform -->
  <link name="base"/>
  <joint name="base_link-base_fixed_joint" type="fixed">
    <!-- NOTE: this rotation is only needed as long as base_link itself is
                 not corrected wrt the real robot (ie: rotated over 180
                 degrees)
      -->
    <origin rpy="0 0 1.5707963" xyz="0 0 0"/>
    <parent link="base"/>
    <child link="base_link"/>
  </joint>

  <link name="base_link">
    <visual>
      <geometry>
        <mesh filename="package://ur_description/meshes/ur10/visual/base.dae"/>
      </geometry>
      <material name="LightGrey">
        <color rgba="0.7 0.7 0.7 1.0"/>
      </material>
    </visual>
    <collision>
      <geometry>
        <mesh filename="package://ur_description/meshes/ur10/collision/base.stl"/>
      </geometry>
    </collision>
    <inertial>
      <mass value="4.0"/>
      <origin rpy="0 0 0" xyz="0.0 0.0 0.0"/>
      <inertia ixx="0.0061063308908" ixy="0.0" ixz="0.0" iyy="0.0061063308908" iyz="0.0" izz="0.01125"/>
    </inertial>
  </link>
  <joint name="shoulder_pan_joint" type="revolute">
    <parent link="base_link"/>
    <child link="shoulder_link"/>
    <origin rpy="0.0 0.0 0.0" xyz="0.0 0.0 0.1273"/>
    <axis xyz="0 0 1"/>
    <limit effort="330.0" lower="-1" upper="1.3" velocity="2.16"/>
    <dynamics damping="0.0" friction="0.0"/>
  </joint>
  <link name="shoulder_link">
    <visual>
      <geometry>
        <mesh filename="package://ur_description/meshes/ur10/visual/shoulder.dae"/>
      </geometry>
      <material name="LightGrey">
        <color rgba="0.7 0.7 0.7 1.0"/>
      </material>
    </visual>
    <collision>
      <geometry>
        <mesh filename="package://ur_description/meshes/ur10/collision/shoulder.stl"/>
      </geometry>
    </collision>
    <inertial>
      <mass value="7.778"/>
      <origin rpy="0 0 0" xyz="0.0 0.0 0.0"/>
      <inertia ixx="0.0314743125769" ixy="0.0" ixz="0.0" iyy="0.0314743125769" iyz="0.0" izz="0.021875625"/>
    </inertial>
  </link>
  <joint name="shoulder_lift_joint" type="revolute">
    <parent link="shoulder_link"/>
    <child link="upper_arm_link"/>
    <origin rpy="0.0 1.57079632679 0.0" xyz="0.0 0.220941 0.0"/>
    <axis xyz="0 1 0"/>
    <limit effort="330.0" lower="-3.14" upper="-0.5" velocity="2.16"/>
    <dynamics damping="0.0" friction="0.0"/>
  </joint>
  <link name="upper_arm_link">
    <visual>
      <geometry>
        <mesh filename="package://ur_description/meshes/ur10/visual/upperarm.dae"/>
      </geometry>
      <material name="LightGrey">
        <color rgba="0.7 0.7 0.7 1.0"/>
      </material>
    </visual>
    <collision>
      <geometry>
        <mesh filename="package://ur_description/meshes/ur10/collision/upperarm.stl"/>
      </geometry>
    </collision>
    <inertial>
      <mass value="12.93"/>
      <origin rpy="0 0 0" xyz="0.0 0.0 0.306"/>
      <inertia ixx="0.421753803798" ixy="0.0" ixz="0.0" iyy="0.421753803798" iyz="0.0" izz="0.036365625"/>
    </inertial>
  </link>
  <joint name="elbow_joint" type="revolute">
    <parent link="upper_arm_link"/>
    <child link="forearm_link"/>
    <origin rpy="0.0 0.0 0.0" xyz="0.0 -0.1719 0.612"/>
    <axis xyz="0 1 0"/>
    <limit effort="150.0" lower="-2.6" upper="0" velocity="3.15"/>
    <dynamics damping="0.0" friction="0.0"/>
  </joint>
  <link name="forearm_link">
    <visual>
      <geometry>
        <mesh filename="package://ur_description/meshes/ur10/visual/forearm.dae"/>
      </geometry>
      <material name="LightGrey">
        <color rgba="0.7 0.7 0.7 1.0"/>
      </material>
    </visual>
    <collision>
      <geometry>
        <mesh filename="package://ur_description/meshes/ur10/collision/forearm.stl"/>
      </geometry>
    </collision>
    <inertial>
      <mass value="3.87"/>
      <origin rpy="0 0 0" xyz="0.0 0.0 0.28615"/>
      <inertia ixx="0.111069694097" ixy="0.0" ixz="0.0" iyy="0.111069694097" iyz="0.0" izz="0.010884375"/>
    </inertial>
  </link>
  <joint name="wrist_1_joint" type="revolute">
    <parent link="forearm_link"/>
    <child link="wrist_1_link"/>
    <origin rpy="0.0 1.57079632679 0.0" xyz="0.0 0.0 0.5723"/>
    <axis xyz="0 1 0"/>
    <limit effort="54.0" lower="1.2" upper="5.2" velocity="3.2"/>
    <dynamics damping="0.0" friction="0.0"/>
  </joint>
  <link name="wrist_1_link">
    <visual>
      <geometry>
        <mesh filename="package://ur_description/meshes/ur10/visual/wrist1.dae"/>
      </geometry>
      <material name="LightGrey">
        <color rgba="0.7 0.7 0.7 1.0"/>
      </material>
    </visual>
    <collision>
      <geometry>
        <mesh filename="package://ur_description/meshes/ur10/collision/wrist1.stl"/>
      </geometry>
    </collision>
    <inertial>
      <mass value="1.96"/>
      <origin rpy="0 0 0" xyz="0.0 0.0 0.0"/>
      <inertia ixx="0.0051082479567" ixy="0.0" ixz="0.0" iyy="0.0051082479567" iyz="0.0" izz="0.0055125"/>
    </inertial>
  </link>
  <joint name="wrist_2_joint" type="revolute">
    <parent link="wrist_1_link"/>
    <child link="wrist_2_link"/>
    <origin rpy="0.0 0.0 0.0" xyz="0.0 0.1149 0.0"/>
    <axis xyz="0 0 1"/>
    <limit effort="54.0" lower="-2.8" upper="0.0" velocity="3.2"/>
    <dynamics damping="0.0" friction="0.0"/>
  </joint>
  <link name="wrist_2_link">
    <visual>
      <geometry>
        <mesh filename="package://ur_description/meshes/ur10/visual/wrist2.dae"/>
      </geometry>
      <material name="LightGrey">
        <color rgba="0.7 0.7 0.7 1.0"/>
      </material>
    </visual>
    <collision>
      <geometry>
        <mesh filename="package://ur_description/meshes/ur10/collision/wrist2.stl"/>
      </geometry>
    </collision>
    <inertial>
      <mass value="1.96"/>
      <origin rpy="0 0 0" xyz="0.0 0.0 0.0"/>
      <inertia ixx="0.0051082479567" ixy="0.0" ixz="0.0" iyy="0.0051082479567" iyz="0.0" izz="0.0055125"/>
    </inertial>
  </link>
  <joint name="wrist_3_joint" type="revolute">
    <parent link="wrist_2_link"/>
    <child link="wrist_3_link"/>
    <origin rpy="0.0 0.0 0.0" xyz="0.0 0.0 0.1157"/>
    <axis xyz="0 1 0"/>
    <limit effort="54.0" lower="-2.6" upper="0.0" velocity="3.2"/>
    <dynamics damping="0.0" friction="0.0"/>
  </joint>
  <link name="wrist_3_link">
    <visual>
      <geometry>
        <mesh filename="package://ur_description/meshes/ur10/visual/wrist3.dae"/>
      </geometry>
      <material name="LightGrey">
        <color rgba="0.7 0.7 0.7 1.0"/>
      </material>
    </visual>
    <collision>
      <geometry>
        <mesh filename="package://ur_description/meshes/ur10/collision/wrist3.stl"/>
      </geometry>
    </collision>
    <inertial>
      <mass value="0.202"/>
      <origin rpy="0 0 0" xyz="0.0 0.0 0.0"/>
      <inertia ixx="0.000526462289415" ixy="0.0" ixz="0.0" iyy="0.000526462289415" iyz="0.0" izz="0.000568125"/>
    </inertial>
  </link>
  <joint name="ee_fixed_joint" type="fixed">
    <parent link="wrist_3_link"/>
    <child link="ee_link"/>
    <origin rpy="0.0 0.0 1.57079632679" xyz="0.0 0.0922 0.0"/>
  </joint>
  <link name="ee_link">
    <collision>
      <geometry>
        <box size="0.01 0.01 0.01"/>
      </geometry>
      <origin rpy="0 0 0" xyz="-0.01 0 0"/>
    </collision>
  </link>



  <link name="tool1">
    <visual>
      <geometry>
        <cylinder length="0.37" radius="0.03"/>
      </geometry>
      <origin rpy="0 1.57 0" xyz="-0.185 0 0"/>
	  <material name="green">
    	<color rgba="0 0.8 0 1"/>
  	  </material>
    </visual>
  </link>
  <joint name="tool0_to_tool1" type="fixed">
    <origin rpy="0 0 0" xyz="0.37 0 0"/>
    <parent link="ee_link"/>
    <child link="tool1"/>
  </joint>

  <link name="gripper0">
  </link>
  <joint name="tool1_to_gripper0" type="fixed">
    <origin rpy="-1.57 -1.57 0" xyz="0.0 0 0"/>
    <parent link="tool1"/>
    <child link="gripper0"/>
  </joint>

  <link name="gripper">
  </link>
  <joint name="gripper0_to_gripper1" type="fixed">
    <origin rpy="0.0 0.0 0" xyz="-0.03 0 0"/>
    <parent link="gripper0"/>
    <child link="gripper"/>
  </joint>

<!--
  <link name="box">
    <visual>
      <geometry>
        <box size="0.08 0.08 0.15"/>
      </geometry>
      <origin rpy="0 0 0" xyz="0 0 0"/>
	  <material name="2">
    	<color rgba="0 1 0 1"/>
  	  </material>
    </visual>
  </link>
  <joint name="gripper_to_box" type="fixed">
    <parent link="gripper"/>
    <child link="box"/>
    <origin rpy="0.0 0.0 0.0" xyz="0 0.05 0.08"/>
  </joint>
-->

  <link name="huojia">
    <visual>
      <geometry>
        <mesh filename="package://ur_description/meshes/huojia1.stl"/>
      </geometry>
    </visual>
  </link>
  <joint name="base_to_huojia" type="fixed">
    <parent link="world"/>
    <child link="huojia"/>
    <origin rpy="0.0 0.0 0" xyz="0 -0.95 0"/>
  </joint>
<!--
  <link name="desk">
    <visual>
      <geometry>
        <mesh filename="package://ur_description/meshes/desk1.stl"/>
      </geometry>
    </visual>
  </link>
  <joint name="base_to_desk" type="fixed">
    <parent link="world"/>
    <child link="desk"/>
    <origin rpy="0.0 0.0 0" xyz="0 -1.05 0"/>
  </joint>
-->

  <link name="wall1">
    <visual>
      <geometry>
        <box size="2 2 0.1"/>
      </geometry>
      <origin rpy="0 0 0" xyz="0 0 0"/>
	  <material name=" ">
    	<color rgba="0 0 1 0.1"/>
  	  </material>
    </visual>
  </link>
  <joint name="agv_to_wall1" type="fixed">
    <parent link="agv"/>
    <child link="wall1"/>
    <origin rpy="0.0 0.0 0.0" xyz="0.3 -0.3 1.75"/>
  </joint>

<!--
  <link name="wall_prm">
    <visual>
      <geometry>
        <box size="1.5 0.06 0.7"/>
      </geometry>
      <origin rpy="0 0 0" xyz="0 0 0.35"/>
	  <material name="a">
    	<color rgba="0 1 0 1"/>
  	  </material>
    </visual>
  </link>
  <joint name="world_to_wallprm" type="fixed">
    <parent link="world"/>
    <child link="wall_prm"/>
    <origin rpy="0.0 0.0 0.0" xyz="0 -1.1 0.35"/>
  </joint>

-->

  <link name="world"/>

  <link name="agv">
    <visual>
      <geometry>
        <box size="0.9 0.64 0.63"/>
      </geometry>
      <origin rpy="0 0 0" xyz="0 0 0.315"/>
	  <material name="green">
    	<color rgba="0 1 0 1"/>
  	  </material>
    </visual>
  </link>
  <joint name="world_to_agv" type="fixed">
    <parent link="world"/>
    <child link="agv"/>
    <origin rpy="0.0 0.0 0" xyz="-0.275 0 0"/>
  </joint>

  <joint name="agv_to_base_link" type="fixed">
    <parent link="agv"/>
    <child link="base"/>
    <origin rpy="0.0 0.0 0" xyz="0.275 0 0.635"/>
  </joint>
<!--
  <link name="basket">
    <visual>
      <geometry>
        <box size="0.4 0.6 0.2"/>
      </geometry>
      <origin rpy="0 0 0" xyz="0 0 0.1"/>
	  <material name="green">
    	<color rgba="0 1 0 1"/>
  	  </material>
    </visual>
  </link>
  <joint name="agv_to_basket" type="fixed">
    <parent link="agv"/>
    <child link="basket"/>
    <origin rpy="0.0 0.0 0" xyz="-0.225 0 0.6"/>
  </joint>
-->

  <link name="camera">
    <visual>
      <geometry>
        <box size="0.1 0.08 0.08"/>
      </geometry>
      <origin rpy="0 0 0" xyz="0 0 0"/>
	  <material name="green">
    	<color rgba="0 1 0 1"/>
  	  </material>
    </visual>
  </link>
  <joint name="ee_to_camera" type="fixed">
    <parent link="ee_link"/>
    <child link="camera"/>
    <origin rpy="0.0 0.0 0.0" xyz="0.1 0.1 0.0"/>
  </joint>

<!--
  <link name="abc1">
  </link>
  <joint name="ee_to_abc1" type="fixed">
    <parent link="ee_link"/>
    <child link="abc1"/>
    <origin rpy="0.0 0.0 0.0" xyz="0.01 0.0 0.0"/>
  </joint>

  <link name="abc2">
  </link>
  <joint name="abc1_to_abc2" type="fixed">
    <parent link="abc1"/>
    <child link="abc2"/>
    <origin rpy="0.0 0.0 0.0" xyz="0.0 0.063 0.0"/>
  </joint>

  <link name="abc3">
  </link>
  <joint name="abc2_to_abc3" type="fixed">
    <parent link="abc2"/>
    <child link="abc3"/>
    <origin rpy="0.0 0.0 1.92" xyz="0.0 0.0 0.0"/>
  </joint>

  <link name="abc4">
  </link>
  <joint name="abc3_to_abc4" type="fixed">
    <parent link="abc3"/>
    <child link="abc4"/>
    <origin rpy="0.0 0.0 0.0" xyz="0.0 -0.1356 0.0"/>
  </joint>

  <link name="abc5">
  </link>
  <joint name="abc4_to_abc5" type="fixed">
    <parent link="abc4"/>
    <child link="abc5"/>
    <origin rpy="0.0 0.0 0.0" xyz="0.013 0.0 0.0"/>
  </joint>

  <link name="abc6">
  </link>
  <joint name="abc5_to_abc6" type="fixed">
    <parent link="abc5"/>
    <child link="abc6"/>
    <origin rpy="1.5708 0.0 0.0" xyz="0.0 0.0 0.0"/>
  </joint>

  <link name="abc7">
  </link>
  <joint name="abc6_to_abc7" type="fixed">
    <parent link="abc6"/>
    <child link="abc7"/>
    <origin rpy="0.0 0.0 1.5708" xyz="0.0 0.0 0.0"/>
  </joint>
-->
</robot>

